Workbook

Sheet Drivers
A1: Caddy 19 — Drivers (all inputs live here)
A3: CORE DRIVERS
A4: Cars per day per crew | B4: 5
A5: Operating days per week | B5: 5
A6: Weeks per month | B6: 4.33
A7: Avg ticket ($) | B7: 165
A8: Number of crews | B8: 1
A9: Tech labor % of revenue | B9: 0.32
A10: Payroll burden % of wages | B10: 0.14
A11: Credit-card processing % of revenue | B11: 0.029
A12: Club revenue share % of revenue | B12: 0.12
A13: Supplies per car ($) | B13: 12
A14: Manager salary $/month (0 if owner/brother takes residual) | B14: 0
A15: Vehicle setup (type "Van" or "Tesla") | B15: Van
A17: COMPUTED
A18: Club-days per month | B18: =B5*B6 -> 21.65
A19: Cars per month per crew | B19: =B4*B18 -> 108.25
A20: Variable cost % of revenue | B20: =B9+B9*B10+B11+B12 -> 0.5138
A22: VAN SETUP — monthly fixed
A23: Lease | B23: 650
A24: Commercial auto insurance | B24: 220
A25: GL + garagekeepers + BOP | B25: 150
A26: Fuel (gas) | B26: 400
A27: Equipment upkeep | B27: 200
A28: Software / booking / phone | B28: 80
A29: Marketing | B29: 150
A30: Misc | B30: 200
A31: Van fixed/mo (SUM) | B31: =SUM(B23:B30) -> 2050
A33: TESLA SETUP — monthly fixed
A34: Lease (Model Y-class; note: Cybertruck ~$1,100/mo) | B34: 750
A35: Commercial auto insurance | B35: 300
A36: GL + garagekeepers + BOP | B36: 150
A37: Charging | B37: 80
A38: Equipment upkeep | B38: 200
A39: Software / booking / phone | B39: 80
A40: Marketing | B40: 150
A41: Misc | B41: 200
A42: Tesla fixed/mo (SUM) | B42: =SUM(B34:B41) -> 1910
A44: ACTIVE FIXED COSTS/MO (drives Projection & Sensitivity) | B44: =IF(B15="Tesla",B42,B31) -> 2050
A46: NOTES
...

Sheet One-Crew Projection
A1: Caddy 19 — One-Crew Projection (Monthly + Annual P&L)
B3: Monthly | C3: Annual
A4: Revenue | B4: =Drivers!B4*Drivers!B18*Drivers!B7*Drivers!B8 -> 17861.25 | C4: =B4*12 -> 214335
A5: Cars serviced/month | B5: =Drivers!B19*Drivers!B8 -> 108.25 | C5: =B5*12 -> 1299
A6: Tech labor | B6: =B4*Drivers!B9 -> 5715.6 | C6: =B6*12 -> 68587.2
A7: Payroll burden | B7: =B6*Drivers!B10 -> 800.184 | C7: =B7*12 -> 9602.208
A8: Credit-card processing | B8: =B4*Drivers!B11 -> 517.97625 | C8: =B8*12 -> 6215.715
A9: Club revenue share | B9: =B4*Drivers!B12 -> 2143.35 | C9: =B9*12 -> 25720.2
A10: Supplies | B10: =B5*Drivers!B13 -> 1299 | C10: =B10*12 -> 15588
A11: Active fixed costs | B11: =Drivers!B44*Drivers!B8 -> 2050 | C11: =B11*12 -> 24600
A12: Manager salary | B12: =Drivers!B14 -> 0 | C12: =B12*12 -> 0
A13: TOTAL COSTS | B13: =SUM(B6:B12) -> 12526.11 | C13: =SUM(C6:C12) -> 150313.32
A15: OWNER/MANAGER CASH FLOW (pre-tax) | B15: =B4-B13 -> 5335.1398 | C15: =C4-C13 -> 64021.677
A16: Operating margin % | B16: =B15/B4 -> 0.29869913 | C16: =C15/C4 -> 0.29869913
A18: At 5 cars/day, 5 days/wk, one Van crew: ~$5,335/mo (~$64k/yr) to the owner/manager. Tesla setup: ~$5,475/mo. Drop to 3 days/wk and it roughly halves -- utilization is everything.

Sheet Van vs Tesla
A1: Caddy 19 — Van vs Tesla (Monthly P&L at current volume)
B3: Van | C3: Tesla | D3: Difference (Tesla - Van)
A4: Revenue | B4: =Drivers!B4*Drivers!B18*Drivers!B7*Drivers!B8 -> 17861.25 | C4: =B4 -> 17861.25 | D4: =C4-B4 -> 0
A5: Tech labor | B5: =B4*Drivers!B9 -> 5715.6 | C5: =C4*Drivers!B9 -> 5715.6
A6: Payroll burden | B6: =B5*Drivers!B10 -> 800.184 | C6: =C5*Drivers!B10 -> 800.184
A7: Credit-card processing | B7: =B4*Drivers!B11 -> 517.97625 | C7: =C4*Drivers!B11 -> 517.97625
A8: Club revenue share | B8: =B4*Drivers!B12 -> 2143.35 | C8: =C4*Drivers!B12 -> 2143.35
A9: Supplies | B9: =Drivers!B19*Drivers!B8*Drivers!B13 -> 1299 | C9: =B9 -> 1299
A10: Total variable costs | B10: =SUM(B5:B9) -> 10476.11 | C10: =SUM(C5:C9) -> 10476.11
A12: FIXED COSTS
A13: Lease | B13: =Drivers!B23 -> 650 | C13: =Drivers!B34 -> 750
A14: Commercial auto insurance | B14: =Drivers!B24 -> 220 | C14: =Drivers!B35 -> 300
A15: GL + garagekeepers + BOP | B15: =Drivers!B25 -> 150 | C15: =Drivers!B36 -> 150
A16: Fuel / Charging | B16: =Drivers!B26 -> 400 | C16: =Drivers!B37 -> 80
A17: Equipment upkeep | B17: =Drivers!B27 -> 200 | C17: =Drivers!B38 -> 200
A18: Software / booking / phone | B18: =Drivers!B28 -> 80 | C18: =Drivers!B39 -> 80
A19: Marketing | B19: =Drivers!B29 -> 150 | C19: =Drivers!B40 -> 150
A20: Misc | B20: =Drivers!B30 -> 200 | C20: =Drivers!B41 -> 200
A21: Total fixed (x crews) | B21: =SUM(B13:B20)*Drivers!B8 -> 2050 | C21: =SUM(C13:C20)*Drivers!B8 -> 1910 | D21: =C21-B21 -> -140
A22: Manager salary | B22: =Drivers!B14 -> 0 | C22: =Drivers!B14 -> 0
A23: TOTAL COSTS | B23: =B10+B21+B22 -> 12526.11 | C23: =C10+C21+C22 -> 12386.11 | D23: =C23-B23 -> -140
A25: OWNER/MANAGER CASH FLOW | B25: =B4-B23 -> 5335.1398 | C25: =C4-C23 -> 5475.1398 | D25: =C25-B25 -> 140
A26: Operating margin % | B26: =B25/B4 -> 0.29869913 | C26: =C25/C4 -> 0.30653732
A28: ONE-TIME STARTUP COSTS
B29: Van | C29: Tesla | D29: Difference (Tesla - Van)
A30: Detailing equipment (pressure washer, generator, water tank, extractor, polisher, vac, reclamation) | B30: 5000 | C30: 5500 | D30: =C30-B30 -> 500
A31: Lease drive-off | B31: 1500 | C31: 2000 | D31: =C31-B31 -> 500
A32: Insurance deposit | B32: 600 | C32: 700 | D32: =C32-B32 -> 100
A33: Brand / print / uniforms | B33: 800 | C33: 800 | D33: =C33-B33 -> 0
A34: Initial supplies | B34: 600 | C34: 600 | D34: =C34-B34 -> 0
A35: Permits / licenses | B35: 150 | C35: 150 | D35: =C35-B35 -> 0
A36: Working capital buffer | B36: 4000 | C36: 4000 | D36: =C36-B36 -> 0
A37: Contingency | B37: 1300 | C37: 1400 | D37: =C37-B37 -> 100
A38: TOTAL | B38: =SUM(B30:B37) -> 13950 | C38: =SUM(C30:C37) -> 15150 | D38: =C38-B38 -> 1200
A40: PROS / CONS / WATCH-OUTS
A41: Van
A42: + Big water capacity handles very dirty cars. - Gas generator is NOISY on a course; gas cost; less premium image.
A43: Tesla
A44: + Silent + premium + electric power fits clubs. + Rinseless/steam method = near-zero runoff (easiest turf/grounds approval). - Lease MILEAGE CAPS (driving club-to-club eats miles); limited water for heavy jobs; pricier power station up front. Note: Cybertruck has stronger built-in outlets (PowerShare) but ~$1,100/mo lease.

Sheet Sensitivity
A1: Caddy 19 — Sensitivity Analysis
A3: GRID A -- Monthly Owner/Manager Cash Flow (one crew): Cars/day x Avg Ticket
A4: Cars/day \ Avg Ticket | B4: 130 | C4: 150 | D4: 165 | E4: 185 | F4: 205
A5: 3 | B5: =($A5*Drivers!$B$18*B$4)-($A5*Drivers!$B$18*B$4*Drivers!$B$20)-($A5*Drivers!$B$18*Drivers!$B$13)-Drivers!$B$44 -> 1275.8297 | C5: =($A5*Drivers!$B$18*C$4)-($A5*Drivers!$B$18*C$4*Drivers!$B$20)-($A5*Drivers!$B$18*Drivers!$B$13)-Drivers!$B$44 -> 1907.4035 | D5: =($A5*Drivers!$B$18*D$4)-($A5*Drivers!$B$18*D$4*Drivers!$B$20)-($A5*Drivers!$B$18*Drivers!$B$13)-Drivers!$B$44 -> 2381.0838 | E5: =($A5*Drivers!$B$18*E$4)-($A5*Drivers!$B$18*E$4*Drivers!$B$20)-($A5*Drivers!$B$18*Drivers!$B$13)-Drivers!$B$44 -> 3012.6577 | F5: =($A5*Drivers!$B$18*F$4)-($A5*Drivers!$B$18*F$4*Drivers!$B$20)-($A5*Drivers!$B$18*Drivers!$B$13)-Drivers!$B$44 -> 3644.2315
A6: 4 | B6: =($A6*Drivers!$B$18*B$4)-($A6*Drivers!$B$18*B$4*Drivers!$B$20)-($A6*Drivers!$B$18*Drivers!$B$13)-Drivers!$B$44 -> 2384.4396 | C6: =($A6*Drivers!$B$18*C$4)-($A6*Drivers!$B$18*C$4*Drivers!$B$20)-($A6*Drivers!$B$18*Drivers!$B$13)-Drivers!$B$44 -> 3226.538 | D6: =($A6*Drivers!$B$18*D$4)-($A6*Drivers!$B$18*D$4*Drivers!$B$20)-($A6*Drivers!$B$18*Drivers!$B$13)-Drivers!$B$44 -> 3858.1118 | E6: =($A6*Drivers!$B$18*E$4)-($A6*Drivers!$B$18*E$4*Drivers!$B$20)-($A6*Drivers!$B$18*Drivers!$B$13)-Drivers!$B$44 -> 4700.2102 | F6: =($A6*Drivers!$B$18*F$4)-($A6*Drivers!$B$18*F$4*Drivers!$B$20)-($A6*Drivers!$B$18*Drivers!$B$13)-Drivers!$B$44 -> 5542.3086
A7: 5 | B7: =($A7*Drivers!$B$18*B$4)-($A7*Drivers!$B$18*B$4*Drivers!$B$20)-($A7*Drivers!$B$18*Drivers!$B$13)-Drivers!$B$44 -> 3493.0495 | C7: =($A7*Drivers!$B$18*C$4)-($A7*Drivers!$B$18*C$4*Drivers!$B$20)-($A7*Drivers!$B$18*Drivers!$B$13)-Drivers!$B$44 -> 4545.6725 | D7: =($A7*Drivers!$B$18*D$4)-($A7*Drivers!$B$18*D$4*Drivers!$B$20)-($A7*Drivers!$B$18*Drivers!$B$13)-Drivers!$B$44 -> 5335.1398 | E7: =($A7*Drivers!$B$18*E$4)-($A7*Drivers!$B$18*E$4*Drivers!$B$20)-($A7*Drivers!$B$18*Drivers!$B$13)-Drivers!$B$44 -> 6387.7627 | F7: =($A7*Drivers!$B$18*F$4)-($A7*Drivers!$B$18*F$4*Drivers!$B$20)-($A7*Drivers!$B$18*Drivers!$B$13)-Drivers!$B$44 -> 7440.3858
A8: 6 | B8: =($A8*Drivers!$B$18*B$4)-($A8*Drivers!$B$18*B$4*Drivers!$B$20)-($A8*Drivers!$B$18*Drivers!$B$13)-Drivers!$B$44 -> 4601.6594 | C8: =($A8*Drivers!$B$18*C$4)-($A8*Drivers!$B$18*C$4*Drivers!$B$20)-($A8*Drivers!$B$18*Drivers!$B$13)-Drivers!$B$44 -> 5864.807 | D8: =($A8*Drivers!$B$18*D$4)-($A8*Drivers!$B$18*D$4*Drivers!$B$20)-($A8*Drivers!$B$18*Drivers!$B$13)-Drivers!$B$44 -> 6812.1677 | E8: =($A8*Drivers!$B$18*E$4)-($A8*Drivers!$B$18*E$4*Drivers!$B$20)-($A8*Drivers!$B$18*Drivers!$B$13)-Drivers!$B$44 -> 8075.3153 | F8: =($A8*Drivers!$B$18*F$4)-($A8*Drivers!$B$18*F$4*Drivers!$B$20)-($A8*Drivers!$B$18*Drivers!$B$13)-Drivers!$B$44 -> 9338.4629
A9: 7 | B9: =($A9*Drivers!$B$18*B$4)-($A9*Drivers!$B$18*B$4*Drivers!$B$20)-($A9*Drivers!$B$18*Drivers!$B$13)-Drivers!$B$44 -> 5710.2693 | C9: =($A9*Drivers!$B$18*C$4)-($A9*Drivers!$B$18*C$4*Drivers!$B$20)-($A9*Drivers!$B$18*Drivers!$B$13)-Drivers!$B$44 -> 7183.9415 | D9: =($A9*Drivers!$B$18*D$4)-($A9*Drivers!$B$18*D$4*Drivers!$B$20)-($A9*Drivers!$B$18*Drivers!$B$13)-Drivers!$B$44 -> 8289.1956 | E9: =($A9*Drivers!$B$18*E$4)-($A9*Drivers!$B$18*E$4*Drivers!$B$20)-($A9*Drivers!$B$18*Drivers!$B$13)-Drivers!$B$44 -> 9762.8679 | F9: =($A9*Drivers!$B$18*F$4)-($A9*Drivers!$B$18*F$4*Drivers!$B$20)-($A9*Drivers!$B$18*Drivers!$B$13)-Drivers!$B$44 -> 11236.54
A10: 8 | B10: =($A10*Drivers!$B$18*B$4)-($A10*Drivers!$B$18*B$4*Drivers!$B$20)-($A10*Drivers!$B$18*Drivers!$B$13)-Drivers!$B$44 -> 6818.8792 | C10: =($A10*Drivers!$B$18*C$4)-($A10*Drivers!$B$18*C$4*Drivers!$B$20)-($A10*Drivers!$B$18*Drivers!$B$13)-Drivers!$B$44 -> 8503.076 | D10: =($A10*Drivers!$B$18*D$4)-($A10*Drivers!$B$18*D$4*Drivers!$B$20)-($A10*Drivers!$B$18*Drivers!$B$13)-Drivers!$B$44 -> 9766.2236 | E10: =($A10*Drivers!$B$18*E$4)-($A10*Drivers!$B$18*E$4*Drivers!$B$20)-($A10*Drivers!$B$18*Drivers!$B$13)-Drivers!$B$44 -> 11450.42 | F10: =($A10*Drivers!$B$18*F$4)-($A10*Drivers!$B$18*F$4*Drivers!$B$20)-($A10*Drivers!$B$18*Drivers!$B$13)-Drivers!$B$44 -> 13134.617
A12: ANNUAL (Grid A x 12)
A13: Cars/day \ Avg Ticket | B13: 130 | C13: 150 | D13: 165 | E13: 185 | F13: 205
A14: 3 | B14: =B5*12 -> 15309.956 | C14: =C5*12 -> 22888.842 | D14: =D5*12 -> 28573.006 | E14: =E5*12 -> 36151.892 | F14: =F5*12 -> 43730.777
A15: 4 | B15: =B6*12 -> 28613.275 | C15: =C6*12 -> 38718.456 | D15: =D6*12 -> 46297.342 | E15: =E6*12 -> 56402.522 | F15: =F6*12 -> 66507.703
A16: 5 | B16: =B7*12 -> 41916.594 | C16: =C7*12 -> 54548.07 | D16: =D7*12 -> 64021.677 | E16: =E7*12 -> 76653.153 | F16: =F7*12 -> 89284.629
A17: 6 | B17: =B8*12 -> 55219.913 | C17: =C8*12 -> 70377.684 | D17: =D8*12 -> 81746.012 | E17: =E8*12 -> 96903.784 | F17: =F8*12 -> 112061.55
A18: 7 | B18: =B9*12 -> 68523.232 | C18: =C9*12 -> 86207.298 | D18: =D9*12 -> 99470.348 | E18: =E9*12 -> 117154.41 | F18: =F9*12 -> 134838.48
A19: 8 | B19: =B10*12 -> 81826.55 | C19: =C10*12 -> 102036.91 | D19: =D10*12 -> 117194.68 | E19: =E10*12 -> 137405.04 | F19: =F10*12 -> 157615.41
A21: GRID B -- Total Monthly Cash Flow, pre-manager: Number of Crews x Cars/day (at Drivers Avg Ticket)
A22: Crews \ Cars/day | B22: 3 | C22: 4 | D22: 5 | E22: 6 | F22: 7
A23: 1 | B23: =$A23*((B$22*Drivers!$B$18*Drivers!$B$7)-(B$22*Drivers!$B$18*Drivers!$B$7*Drivers!$B$20)-(B$22*Drivers!$B$18*Drivers!$B$13)-Drivers!$B$44) -> 2381.0838 | C23: =$A23*((C$22*Drivers!$B$18*Drivers!$B$7)-(C$22*Drivers!$B$18*Drivers!$B$7*Drivers!$B$20)-(C$22*Drivers!$B$18*Drivers!$B$13)-Drivers!$B$44) -> 3858.1118 | D23: =$A23*((D$22*Drivers!$B$18*Drivers!$B$7)-(D$22*Drivers!$B$18*Drivers!$B$7*Drivers!$B$20)-(D$22*Drivers!$B$18*Drivers!$B$13)-Drivers!$B$44) -> 5335.1398 | E23: =$A23*((E$22*Drivers!$B$18*Drivers!$B$7)-(E$22*Drivers!$B$18*Drivers!$B$7*Drivers!$B$20)-(E$22*Drivers!$B$18*Drivers!$B$13)-Drivers!$B$44) -> 6812.1677 | F23: =$A23*((F$22*Drivers!$B$18*Drivers!$B$7)-(F$22*Drivers!$B$18*Drivers!$B$7*Drivers!$B$20)-(F$22*Drivers!$B$18*Drivers!$B$13)-Drivers!$B$44) -> 8289.1956
A24: 2 | B24: =$A24*((B$22*Drivers!$B$18*Drivers!$B$7)-(B$22*Drivers!$B$18*Drivers!$B$7*Drivers!$B$20)-(B$22*Drivers!$B$18*Drivers!$B$13)-Drivers!$B$44) -> 4762.1677 | C24: =$A24*((C$22*Drivers!$B$18*Drivers!$B$7)-(C$22*Drivers!$B$18*Drivers!$B$7*Drivers!$B$20)-(C$22*Drivers!$B$18*Drivers!$B$13)-Drivers!$B$44) -> 7716.2236 | D24: =$A24*((D$22*Drivers!$B$18*Drivers!$B$7)-(D$22*Drivers!$B$18*Drivers!$B$7*Drivers!$B$20)-(D$22*Drivers!$B$18*Drivers!$B$13)-Drivers!$B$44) -> 10670.28 | E24: =$A24*((E$22*Drivers!$B$18*Drivers!$B$7)-(E$22*Drivers!$B$18*Drivers!$B$7*Drivers!$B$20)-(E$22*Drivers!$B$18*Drivers!$B$13)-Drivers!$B$44) -> 13624.335 | F24: =$A24*((F$22*Drivers!$B$18*Drivers!$B$7)-(F$22*Drivers!$B$18*Drivers!$B$7*Drivers!$B$20)-(F$22*Drivers!$B$18*Drivers!$B$13)-Drivers!$B$44) -> 16578.391
A25: 3 | B25: =$A25*((B$22*Drivers!$B$18*Drivers!$B$7)-(B$22*Drivers!$B$18*Drivers!$B$7*Drivers!$B$20)-(B$22*Drivers!$B$18*Drivers!$B$13)-Drivers!$B$44) -> 7143.2515 | C25: =$A25*((C$22*Drivers!$B$18*Drivers!$B$7)-(C$22*Drivers!$B$18*Drivers!$B$7*Drivers!$B$20)-(C$22*Drivers!$B$18*Drivers!$B$13)-Drivers!$B$44) -> 11574.335 | D25: =$A25*((D$22*Drivers!$B$18*Drivers!$B$7)-(D$22*Drivers!$B$18*Drivers!$B$7*Drivers!$B$20)-(D$22*Drivers!$B$18*Drivers!$B$13)-Drivers!$B$44) -> 16005.419 | E25: =$A25*((E$22*Drivers!$B$18*Drivers!$B$7)-(E$22*Drivers!$B$18*Drivers!$B$7*Drivers!$B$20)-(E$22*Drivers!$B$18*Drivers!$B$13)-Drivers!$B$44) -> 20436.503 | F25: =$A25*((F$22*Drivers!$B$18*Drivers!$B$7)-(F$22*Drivers!$B$18*Drivers!$B$7*Drivers!$B$20)-(F$22*Drivers!$B$18*Drivers!$B$13)-Drivers!$B$44) -> 24867.587
A26: 4 | B26: =$A26*((B$22*Drivers!$B$18*Drivers!$B$7)-(B$22*Drivers!$B$18*Drivers!$B$7*Drivers!$B$20)-(B$22*Drivers!$B$18*Drivers!$B$13)-Drivers!$B$44) -> 9524.3354 | C26: =$A26*((C$22*Drivers!$B$18*Drivers!$B$7)-(C$22*Drivers!$B$18*Drivers!$B$7*Drivers!$B$20)-(C$22*Drivers!$B$18*Drivers!$B$13)-Drivers!$B$44) -> 15432.447 | D26: =$A26*((D$22*Drivers!$B$18*Drivers!$B$7)-(D$22*Drivers!$B$18*Drivers!$B$7*Drivers!$B$20)-(D$22*Drivers!$B$18*Drivers!$B$13)-Drivers!$B$44) -> 21340.559 | E26: =$A26*((E$22*Drivers!$B$18*Drivers!$B$7)-(E$22*Drivers!$B$18*Drivers!$B$7*Drivers!$B$20)-(E$22*Drivers!$B$18*Drivers!$B$13)-Drivers!$B$44) -> 27248.671 | F26: =$A26*((F$22*Drivers!$B$18*Drivers!$B$7)-(F$22*Drivers!$B$18*Drivers!$B$7*Drivers!$B$20)-(F$22*Drivers!$B$18*Drivers!$B$13)-Drivers!$B$44) -> 33156.783
A27: 5 | B27: =$A27*((B$22*Drivers!$B$18*Drivers!$B$7)-(B$22*Drivers!$B$18*Drivers!$B$7*Drivers!$B$20)-(B$22*Drivers!$B$18*Drivers!$B$13)-Drivers!$B$44) -> 11905.419 | C27: =$A27*((C$22*Drivers!$B$18*Drivers!$B$7)-(C$22*Drivers!$B$18*Drivers!$B$7*Drivers!$B$20)-(C$22*Drivers!$B$18*Drivers!$B$13)-Drivers!$B$44) -> 19290.559 | D27: =$A27*((D$22*Drivers!$B$18*Drivers!$B$7)-(D$22*Drivers!$B$18*Drivers!$B$7*Drivers!$B$20)-(D$22*Drivers!$B$18*Drivers!$B$13)-Drivers!$B$44) -> 26675.699 | E27: =$A27*((E$22*Drivers!$B$18*Drivers!$B$7)-(E$22*Drivers!$B$18*Drivers!$B$7*Drivers!$B$20)-(E$22*Drivers!$B$18*Drivers!$B$13)-Drivers!$B$44) -> 34060.838 | F27: =$A27*((F$22*Drivers!$B$18*Drivers!$B$7)-(F$22*Drivers!$B$18*Drivers!$B$7*Drivers!$B$20)-(F$22*Drivers!$B$18*Drivers!$B$13)-Drivers!$B$44) -> 41445.978
A28: 6 | B28: =$A28*((B$22*Drivers!$B$18*Drivers!$B$7)-(B$22*Drivers!$B$18*Drivers!$B$7*Drivers!$B$20)-(B$22*Drivers!$B$18*Drivers!$B$13)-Drivers!$B$44) -> 14286.503 | C28: =$A28*((C$22*Drivers!$B$18*Drivers!$B$7)-(C$22*Drivers!$B$18*Drivers!$B$7*Drivers!$B$20)-(C$22*Drivers!$B$18*Drivers!$B$13)-Drivers!$B$44) -> 23148.671 | D28: =$A28*((D$22*Drivers!$B$18*Drivers!$B$7)-(D$22*Drivers!$B$18*Drivers!$B$7*Drivers!$B$20)-(D$22*Drivers!$B$18*Drivers!$B$13)-Drivers!$B$44) -> 32010.839 | E28: =$A28*((E$22*Drivers!$B$18*Drivers!$B$7)-(E$22*Drivers!$B$18*Drivers!$B$7*Drivers!$B$20)-(E$22*Drivers!$B$18*Drivers!$B$13)-Drivers!$B$44) -> 40873.006 | F28: =$A28*((F$22*Drivers!$B$18*Drivers!$B$7)-(F$22*Drivers!$B$18*Drivers!$B$7*Drivers!$B$20)-(F$22*Drivers!$B$18*Drivers!$B$13)-Drivers!$B$44) -> 49735.174
A30: Grid B excludes a dedicated manager salary -- add ~$6,600/mo once you hire one (typically around 4+ crews). One crew's residual IS the owner/manager income.

Sheet Clubs & Members Needed
A1: Caddy 19 — Clubs & Members Needed (how many clubs keep a crew busy)
A3: INPUTS
A4: Avg golf members per club | B4: 450
A5: Monthly detail rate (% of members detailing / month) | B5: 0.1
A6: e.g., 5% recurring-plan (1/mo) + 5% occasional = 10%
A8: DEMAND TARGET (auto-pulled from Drivers)
A9: Cars/month needed — per crew | B9: =Drivers!B19 -> 108.25
A10: Number of crews | B10: =Drivers!B8 -> 1
A11: Total cars/month needed | B11: =B9*B10 -> 108.25
A13: SUPPLY PER CLUB
A14: Details supplied per club / month | B14: =B4*B5 -> 45
A15: Club-days/week one club fills | B15: =B14/Drivers!B4/Drivers!B6 -> 2.0785219
A17: RESULT
A18: ▶ Clubs needed to keep ONE crew busy | B18: =ROUNDUP(B9/B14,0) -> 3
A19: ▶ Clubs needed for ALL crews | B19: =ROUNDUP(B11/B14,0) -> 3
A20: Members detailing/month across those clubs | B20: =B18*B4*B5 -> 135
A21: ≈ your recurring-member base if most are on monthly plans
A24: CLUBS NEEDED FOR ONE CREW — Monthly detail rate (rows) × Avg club size (cols)
A25: detail rate \ club size | B25: 250 | C25: 350 | D25: 450 | E25: 550 | F25: 700
A26: 0.04 | B26: =ROUNDUP($B$9/(B$25*$A26),0) -> 11 | C26: =ROUNDUP($B$9/(C$25*$A26),0) -> 8 | D26: =ROUNDUP($B$9/(D$25*$A26),0) -> 7 | E26: =ROUNDUP($B$9/(E$25*$A26),0) -> 5 | F26: =ROUNDUP($B$9/(F$25*$A26),0) -> 4
A27: 0.06 | B27: =ROUNDUP($B$9/(B$25*$A27),0) -> 8 | C27: =ROUNDUP($B$9/(C$25*$A27),0) -> 6 | D27: =ROUNDUP($B$9/(D$25*$A27),0) -> 5 | E27: =ROUNDUP($B$9/(E$25*$A27),0) -> 4 | F27: =ROUNDUP($B$9/(F$25*$A27),0) -> 3
A28: 0.08 | B28: =ROUNDUP($B$9/(B$25*$A28),0) -> 6 | C28: =ROUNDUP($B$9/(C$25*$A28),0) -> 4 | D28: =ROUNDUP($B$9/(D$25*$A28),0) -> 4 | E28: =ROUNDUP($B$9/(E$25*$A28),0) -> 3 | F28: =ROUNDUP($B$9/(F$25*$A28),0) -> 2
A29: 0.1 | B29: =ROUNDUP($B$9/(B$25*$A29),0) -> 5 | C29: =ROUNDUP($B$9/(C$25*$A29),0) -> 4 | D29: =ROUNDUP($B$9/(D$25*$A29),0) -> 3 | E29: =ROUNDUP($B$9/(E$25*$A29),0) -> 2 | F29: =ROUNDUP($B$9/(F$25*$A29),0) -> 2
A30: 0.12 | B30: =ROUNDUP($B$9/(B$25*$A30),0) -> 4 | C30: =ROUNDUP($B$9/(C$25*$A30),0) -> 3 | D30: =ROUNDUP($B$9/(D$25*$A30),0) -> 3 | E30: =ROUNDUP($B$9/(E$25*$A30),0) -> 2 | F30: =ROUNDUP($B$9/(F$25*$A30),0) -> 2
A31: 0.15 | B31: =ROUNDUP($B$9/(B$25*$A31),0) -> 3 | C31: =ROUNDUP($B$9/(C$25*$A31),0) -> 3 | D31: =ROUNDUP($B$9/(D$25*$A31),0) -> 2 | E31: =ROUNDUP($B$9/(E$25*$A31),0) -> 2 | F31: =ROUNDUP($B$9/(F$25*$A31),0) -> 2
A33: Notes
A34: • "Detail rate" = share of a club's golf members who get a detail in a given month (plan + occasional).
A35: • Weekend demand clusters Sat/Sun; recurring memberships are what fill Tue–Thu. Cluster clubs geographically (one crew = one club/day).
A36: • Clubs are rounded UP to whole clubs — you can't book half a club.
